Workbook

Sheet Overview
A1: Financial plan overview
B8: Year 1
B38: Year 2
B69: Year 3

Sheet Package details
A1: Package details
A8: Package 1 - Bronze
C9: Specs | D9: Description
A10: CPU: | C10: 1 | D10: This will be one core of the host hardware machine.
A11: RAM: | C11: 2
A12: Disk allocation: | C12: 250
A14: Host hardware: | C14: ='Hardware details'!C10:D10 -> Dell server
A16: Package price: | C16: 17.5
A17: Variable costs: | C17: ='Variable costs'!I17 -> 0.28472222
A18: Contribution margin: | C18: =C16-C17 -> 17.215278
A20: Package 2 - Silver
C21: Specs | D21: Description
A22: CPU: | C22: 1.5 | D22: This will be one core of the host hardware machine.
A23: RAM: | C23: 4
A24: Disk allocation: | C24: 500
A26: Host hardware: | C26: ='Hardware details'!E10 -> Dell server
A28: Package price: | C28: 22.5
A29: Variable costs: | C29: ='Variable costs'!I18 -> 0.52777778
A30: Contribution margin: | C30: =C28-C29 -> 21.972222
A32: Package 3 - Gold
C33: Specs | D33: Description
A34: CPU: | C34: 2 | D34: This will be one core of the host hardware machine.
A35: RAM: | C35: 6
A36: Disk allocation: | C36: 1000
A38: Host hardware: | C38: ='Hardware details'!G10 -> Dell server
A40: Package price: | C40: 27.5
A41: Variable costs: | C41: ='Variable costs'!I19 -> 1.0138889
A42: Contribution margin: | C42: =C40-C41 -> 26.486111

Sheet Hardware details
A1: Hardware details
A8: Host machines
C9: Package 1 - Bronze | E9: Package 2 - Silver | G9: Package 3 - Gold
A10: Hardware name | C10: Dell server | E10: Dell server | G10: Dell server
A11: Average use per server | C11: 0.005 | E11: 0.01 | G11: 0.02
A12: Price to buy | C12: 1750 | E12: =C12 -> 1750 | G12: =C12 -> 1750
A13: № virtual machines | C13: =1/C11 -> 200 | E13: =1/E11 -> 100 | G13: =1/G11 -> 50
A14: CPU | C14: 2 Intel Xeon (20 cores) | E14: 2 Intel Xeon (20 cores) | G14: 2 Intel Xeon (20 cores)
A15: RAM | C15: 32 | E15: 32 | G15: 32
A16: Disk allocation | C16: SAN | E16: SAN | G16: SAN
A17: Other specifications
A19: Network pheripicals
C20: Router | E20: Switch | G20: Hardware firewall | I20: Dedicated web server
A21: Hardware name | C21: Router | E21: Switch
A22: Price to buy | C22: 1500 | E22: 1000 | I22: 2000
A23: № virtual machines | C23: 1000 | E23: =30000 -> 30000 | I23: n/a
A24: Specifications

Sheet Sales forecast
A1: Sales forecast
A9: Year 1 | B9: January | C9: February | D9: March | E9: April | F9: May | G9: June | H9: July | I9: August | J9: September | K9: October | L9: November | M9: December | O9: Total new sold packages
A10: Bronze | B10: =($O$10/12) -> 52.083333 | C10: =B10+($O$10/12) -> 104.16667 | D10: =C10+($O$10/12) -> 156.25 | E10: =D10+($O$10/12) -> 208.33333 | F10: =E10+($O$10/12) -> 260.41667 | G10: =F10+($O$10/12) -> 312.5 | H10: =G10+($O$10/12) -> 364.58333 | I10: =H10+($O$10/12) -> 416.66667 | J10: =I10+($O$10/12) -> 468.75 | ... M10: =L10+($O$10/12) -> 625 | O10: =O13*P10 -> 625 | P10: 0.25
A11: Silver | B11: =($O$11/12) -> 104.16667 | C11: =B11+($O$11/12) -> 208.33333 | D11: =C11+($O$11/12) -> 312.5 | E11: =D11+($O$11/12) -> 416.66667 | F11: =E11+($O$11/12) -> 520.83333 | G11: =F11+($O$11/12) -> 625 | H11: =G11+($O$11/12) -> 729.16667 | I11: =H11+($O$11/12) -> 833.33333 | J11: =I11+($O$11/12) -> 937.5 | ... M11: =L11+($O$11/12) -> 1250 | O11: =O13*P11 -> 1250 | P11: 0.5
A12: Gold | B12: =($O$12/12) -> 52.083333 | C12: =B12+($O$12/12) -> 104.16667 | D12: =C12+($O$12/12) -> 156.25 | E12: =D12+($O$12/12) -> 208.33333 | F12: =E12+($O$12/12) -> 260.41667 | G12: =F12+($O$12/12) -> 312.5 | H12: =G12+($O$12/12) -> 364.58333 | I12: =H12+($O$12/12) -> 416.66667 | J12: =I12+($O$12/12) -> 468.75 | ... M12: =L12+($O$12/12) -> 625 | O12: =O13*P12 -> 625 | P12: 0.25
O13: 2500 | P13: 1
A16: Year 2 | B16: January | C16: February | D16: March | E16: April | F16: May | G16: June | H16: July | I16: August | J16: September | K16: October | L16: November | M16: December | O16: =O9 -> Total new sold packages
A17: Bronze | B17: =M10+($O$17/12) -> 729.16667 | C17: =B17+($O$17/12) -> 833.33333 | D17: =C17+($O$17/12) -> 937.5 | E17: =D17+($O$17/12) -> 1041.6667 | F17: =E17+($O$17/12) -> 1145.8333 | G17: =F17+($O$17/12) -> 1250 | H17: =G17+($O$17/12) -> 1354.1667 | I17: =H17+($O$17/12) -> 1458.3333 | J17: =I17+($O$17/12) -> 1562.5 | ... M17: =L17+($O$17/12) -> 1875 | O17: =O20*P17 -> 1250 | P17: 0.25
A18: Silver | B18: =M11+($O$18/12) -> 1458.3333 | C18: =B18+($O$18/12) -> 1666.6667 | D18: =C18+($O$18/12) -> 1875 | E18: =D18+($O$18/12) -> 2083.3333 | F18: =E18+($O$18/12) -> 2291.6667 | G18: =F18+($O$18/12) -> 2500 | H18: =G18+($O$18/12) -> 2708.3333 | I18: =H18+($O$18/12) -> 2916.6667 | J18: =I18+($O$18/12) -> 3125 | ... M18: =L18+($O$18/12) -> 3750 | O18: =O20*P18 -> 2500 | P18: 0.5
A19: Gold | B19: =M12+($O$19/12) -> 729.16667 | C19: =B19+($O$19/12) -> 833.33333 | D19: =C19+($O$19/12) -> 937.5 | E19: =D19+($O$19/12) -> 1041.6667 | F19: =E19+($O$19/12) -> 1145.8333 | G19: =F19+($O$19/12) -> 1250 | H19: =G19+($O$19/12) -> 1354.1667 | I19: =H19+($O$19/12) -> 1458.3333 | J19: =I19+($O$19/12) -> 1562.5 | ... M19: =L19+($O$19/12) -> 1875 | O19: =O20*P19 -> 1250 | P19: 0.25
O20: 5000 | P20: 1
A23: Year 3 | B23: January | C23: February | D23: March | E23: April | F23: May | G23: June | H23: July | I23: August | J23: September | K23: October | L23: November | M23: December | O23: =O9 -> Total new sold packages
A24: Bronze | B24: =M17+($O$24/12) -> 2083.3333 | C24: =B24+($O$24/12) -> 2291.6667 | D24: =C24+($O$24/12) -> 2500 | E24: =D24+($O$24/12) -> 2708.3333 | F24: =E24+($O$24/12) -> 2916.6667 | G24: =F24+($O$24/12) -> 3125 | H24: =G24+($O$24/12) -> 3333.3333 | I24: =H24+($O$24/12) -> 3541.6667 | J24: =I24+($O$24/12) -> 3750 | ... M24: =L24+($O$24/12) -> 4375 | O24: =O27*P24 -> 2500 | P24: 0.25
A25: Silver | B25: =M18+($O$25/12) -> 4166.6667 | C25: =B25+($O$25/12) -> 4583.3333 | D25: =C25+($O$25/12) -> 5000 | E25: =D25+($O$25/12) -> 5416.6667 | F25: =E25+($O$25/12) -> 5833.3333 | G25: =F25+($O$25/12) -> 6250 | H25: =G25+($O$25/12) -> 6666.6667 | I25: =H25+($O$25/12) -> 7083.3333 | J25: =I25+($O$25/12) -> 7500 | ... M25: =L25+($O$25/12) -> 8750 | O25: =O27*P25 -> 5000 | P25: 0.5
A26: Gold | B26: =M19+($O$26/12) -> 2083.3333 | C26: =B26+($O$26/12) -> 2291.6667 | D26: =C26+($O$26/12) -> 2500 | E26: =D26+($O$26/12) -> 2708.3333 | F26: =E26+($O$26/12) -> 2916.6667 | G26: =F26+($O$26/12) -> 3125 | H26: =G26+($O$26/12) -> 3333.3333 | I26: =H26+($O$26/12) -> 3541.6667 | J26: =I26+($O$26/12) -> 3750 | ... M26: =L26+($O$26/12) -> 4375 | O26: =O27*P26 -> 2500 | P26: 0.25
O27: 10000 | P27: 1

Sheet Hardware demands
A1: Hardware demands
A9: Year 1 | B9: January | C9: February | D9: March | E9: April | F9: May | G9: June | H9: July | I9: August | J9: September | K9: October | L9: November | M9: December
A10: Bronze physical | B10: =ROUNDUP('Sales forecast'!B10/'Variable costs'!$C12,0) -> 1 | C10: =ROUNDUP('Sales forecast'!C10/'Variable costs'!$C12,0) -> 1 | D10: =ROUNDUP('Sales forecast'!D10/'Variable costs'!$C12,0) -> 1 | E10: =ROUNDUP('Sales forecast'!E10/'Variable costs'!$C12,0) -> 2 | F10: =ROUNDUP('Sales forecast'!F10/'Variable costs'!$C12,0) -> 2 | G10: =ROUNDUP('Sales forecast'!G10/'Variable costs'!$C12,0) -> 2 | H10: =ROUNDUP('Sales forecast'!H10/'Variable costs'!$C12,0) -> 2 | I10: =ROUNDUP('Sales forecast'!I10/'Variable costs'!$C12,0) -> 3 | ... M10: =ROUNDUP('Sales forecast'!M10/'Variable costs'!$C12,0) -> 4
A11: Silver physical | B11: =ROUNDUP('Sales forecast'!B11/'Variable costs'!$C13,0) -> 2 | C11: =ROUNDUP('Sales forecast'!C11/'Variable costs'!$C13,0) -> 3 | D11: =ROUNDUP('Sales forecast'!D11/'Variable costs'!$C13,0) -> 4 | E11: =ROUNDUP('Sales forecast'!E11/'Variable costs'!$C13,0) -> 5 | F11: =ROUNDUP('Sales forecast'!F11/'Variable costs'!$C13,0) -> 6 | G11: =ROUNDUP('Sales forecast'!G11/'Variable costs'!$C13,0) -> 7 | H11: =ROUNDUP('Sales forecast'!H11/'Variable costs'!$C13,0) -> 8 | I11: =ROUNDUP('Sales forecast'!I11/'Variable costs'!$C13,0) -> 9 | ... M11: =ROUNDUP('Sales forecast'!M11/'Variable costs'!$C13,0) -> 13
A12: Gold physical | B12: =ROUNDUP('Sales forecast'!B12/'Variable costs'!$C14,0) -> 2 | C12: =ROUNDUP('Sales forecast'!C12/'Variable costs'!$C14,0) -> 3 | D12: =ROUNDUP('Sales forecast'!D12/'Variable costs'!$C14,0) -> 4 | E12: =ROUNDUP('Sales forecast'!E12/'Variable costs'!$C14,0) -> 5 | F12: =ROUNDUP('Sales forecast'!F12/'Variable costs'!$C14,0) -> 6 | G12: =ROUNDUP('Sales forecast'!G12/'Variable costs'!$C14,0) -> 7 | H12: =ROUNDUP('Sales forecast'!H12/'Variable costs'!$C14,0) -> 8 | I12: =ROUNDUP('Sales forecast'!I12/'Variable costs'!$C14,0) -> 9 | ... M12: =ROUNDUP('Sales forecast'!M12/'Variable costs'!$C14,0) -> 13
A13: Routers | B13: 2 | C13: =ROUNDUP(SUM('Sales forecast'!C$10:C$12)/'Variable costs'!$C$15,0) -> 1 | D13: =ROUNDUP(SUM('Sales forecast'!D$10:D$12)/'Variable costs'!$C$15,0) -> 1 | E13: =ROUNDUP(SUM('Sales forecast'!E$10:E$12)/'Variable costs'!$C$15,0) -> 1 | F13: =ROUNDUP(SUM('Sales forecast'!F$10:F$12)/'Variable costs'!$C$15,0) -> 2 | G13: =ROUNDUP(SUM('Sales forecast'!G$10:G$12)/'Variable costs'!$C$15,0) -> 2 | H13: =ROUNDUP(SUM('Sales forecast'!H$10:H$12)/'Variable costs'!$C$15,0) -> 2 | I13: =ROUNDUP(SUM('Sales forecast'!I$10:I$12)/'Variable costs'!$C$15,0) -> 2 | J13: =ROUNDUP(SUM('Sales forecast'!J$10:J$12)/'Variable costs'!$C$15,0) -> 2 | ... M13: =ROUNDUP(SUM('Sales forecast'!M$10:M$12)/'Variable costs'!$C$15,0) -> 3
A14: Switches | B14: =ROUNDUP(SUM('Sales forecast'!B$10:B$12)/'Variable costs'!C16,0) -> 1 | C14: =ROUNDUP(SUM('Sales forecast'!C$10:C$12)/'Variable costs'!$C16,0) -> 1 | D14: =ROUNDUP(SUM('Sales forecast'!D$10:D$12)/'Variable costs'!$C16,0) -> 1 | E14: =ROUNDUP(SUM('Sales forecast'!E$10:E$12)/'Variable costs'!$C16,0) -> 1 | F14: =ROUNDUP(SUM('Sales forecast'!F$10:F$12)/'Variable costs'!$C16,0) -> 1 | G14: =ROUNDUP(SUM('Sales forecast'!G$10:G$12)/'Variable costs'!$C16,0) -> 1 | H14: =ROUNDUP(SUM('Sales forecast'!H$10:H$12)/'Variable costs'!$C16,0) -> 1 | I14: =ROUNDUP(SUM('Sales forecast'!I$10:I$12)/'Variable costs'!$C16,0) -> 1 | J14: =ROUNDUP(SUM('Sales forecast'!J$10:J$12)/'Variable costs'!$C16,0) -> 1 | ... M14: =ROUNDUP(SUM('Sales forecast'!M$10:M$12)/'Variable costs'!$C16,0) -> 1
A17: Year 2 | B17: January | C17: February | D17: March | E17: April | F17: May | G17: June | H17: July | I17: August | J17: September | K17: October | L17: November | M17: December
A18: =A10 -> Bronze physical | B18: =ROUNDUP('Sales forecast'!B17/'Variable costs'!$C12,0) -> 4 | C18: =ROUNDUP('Sales forecast'!C17/'Variable costs'!$C12,0) -> 5 | D18: =ROUNDUP('Sales forecast'!D17/'Variable costs'!$C12,0) -> 5 | E18: =ROUNDUP('Sales forecast'!E17/'Variable costs'!$C12,0) -> 6 | F18: =ROUNDUP('Sales forecast'!F17/'Variable costs'!$C12,0) -> 6 | G18: =ROUNDUP('Sales forecast'!G17/'Variable costs'!$C12,0) -> 7 | H18: =ROUNDUP('Sales forecast'!H17/'Variable costs'!$C12,0) -> 7 | I18: =ROUNDUP('Sales forecast'!I17/'Variable costs'!$C12,0) -> 8 | ... M18: =ROUNDUP('Sales forecast'!M17/'Variable costs'!$C12,0) -> 10
A19: =A11 -> Silver physical | B19: =ROUNDUP('Sales forecast'!B18/'Variable costs'!$C13,0) -> 15 | C19: =ROUNDUP('Sales forecast'!C18/'Variable costs'!$C13,0) -> 17 | D19: =ROUNDUP('Sales forecast'!D18/'Variable costs'!$C13,0) -> 19 | E19: =ROUNDUP('Sales forecast'!E18/'Variable costs'!$C13,0) -> 21 | F19: =ROUNDUP('Sales forecast'!F18/'Variable costs'!$C13,0) -> 23 | G19: =ROUNDUP('Sales forecast'!G18/'Variable costs'!$C13,0) -> 25 | H19: =ROUNDUP('Sales forecast'!H18/'Variable costs'!$C13,0) -> 28 | I19: =ROUNDUP('Sales forecast'!I18/'Variable costs'!$C13,0) -> 30 | ... M19: =ROUNDUP('Sales forecast'!M18/'Variable costs'!$C13,0) -> 38
A20: =A12 -> Gold physical | B20: =ROUNDUP('Sales forecast'!B19/'Variable costs'!$C14,0) -> 15 | C20: =ROUNDUP('Sales forecast'!C19/'Variable costs'!$C14,0) -> 17 | D20: =ROUNDUP('Sales forecast'!D19/'Variable costs'!$C14,0) -> 19 | E20: =ROUNDUP('Sales forecast'!E19/'Variable costs'!$C14,0) -> 21 | F20: =ROUNDUP('Sales forecast'!F19/'Variable costs'!$C14,0) -> 23 | G20: =ROUNDUP('Sales forecast'!G19/'Variable costs'!$C14,0) -> 25 | H20: =ROUNDUP('Sales forecast'!H19/'Variable costs'!$C14,0) -> 28 | I20: =ROUNDUP('Sales forecast'!I19/'Variable costs'!$C14,0) -> 30 | ... M20: =ROUNDUP('Sales forecast'!M19/'Variable costs'!$C14,0) -> 38
A21: =A13 -> Routers | B21: =ROUNDUP(SUM('Sales forecast'!B$17:B$19)/'Variable costs'!$C$15,0) -> 3 | C21: =ROUNDUP(SUM('Sales forecast'!C$17:C$19)/'Variable costs'!$C$15,0) -> 4 | D21: =ROUNDUP(SUM('Sales forecast'!D$17:D$19)/'Variable costs'!$C$15,0) -> 4 | E21: =ROUNDUP(SUM('Sales forecast'!E$17:E$19)/'Variable costs'!$C$15,0) -> 5 | F21: =ROUNDUP(SUM('Sales forecast'!F$17:F$19)/'Variable costs'!$C$15,0) -> 5 | G21: =ROUNDUP(SUM('Sales forecast'!G$17:G$19)/'Variable costs'!$C$15,0) -> 5 | H21: =ROUNDUP(SUM('Sales forecast'!H$17:H$19)/'Variable costs'!$C$15,0) -> 6 | I21: =ROUNDUP(SUM('Sales forecast'!I$17:I$19)/'Variable costs'!$C$15,0) -> 6 | ... M21: =ROUNDUP(SUM('Sales forecast'!M$17:M$19)/'Variable costs'!$C$15,0) -> 8
A22: =A14 -> Switches | B22: =ROUNDUP(SUM('Sales forecast'!B$17:B$19)/'Variable costs'!$C$16,0) -> 1 | C22: =ROUNDUP(SUM('Sales forecast'!C$17:C$19)/'Variable costs'!$C$16,0) -> 1 | D22: =ROUNDUP(SUM('Sales forecast'!D$17:D$19)/'Variable costs'!$C$16,0) -> 1 | E22: =ROUNDUP(SUM('Sales forecast'!E$17:E$19)/'Variable costs'!$C$16,0) -> 1 | F22: =ROUNDUP(SUM('Sales forecast'!F$17:F$19)/'Variable costs'!$C$16,0) -> 1 | G22: =ROUNDUP(SUM('Sales forecast'!G$17:G$19)/'Variable costs'!$C$16,0) -> 1 | H22: =ROUNDUP(SUM('Sales forecast'!H$17:H$19)/'Variable costs'!$C$16,0) -> 1 | I22: =ROUNDUP(SUM('Sales forecast'!I$17:I$19)/'Variable costs'!$C$16,0) -> 1 | ... M22: =ROUNDUP(SUM('Sales forecast'!M$17:M$19)/'Variable costs'!$C$16,0) -> 1
A24: Year 3 | B24: January | C24: February | D24: March | E24: April | F24: May | G24: June | H24: July | I24: August | J24: September | K24: October | L24: November | M24: December
A25: =A10 -> Bronze physical | B25: =ROUNDUP('Sales forecast'!B$24/'Variable costs'!$C$12,0) -> 11 | C25: =ROUNDUP('Sales forecast'!C$24/'Variable costs'!$C$12,0) -> 12 | D25: =ROUNDUP('Sales forecast'!D$24/'Variable costs'!$C$12,0) -> 13 | E25: =ROUNDUP('Sales forecast'!E$24/'Variable costs'!$C$12,0) -> 14 | F25: =ROUNDUP('Sales forecast'!F$24/'Variable costs'!$C$12,0) -> 15 | G25: =ROUNDUP('Sales forecast'!G$24/'Variable costs'!$C$12,0) -> 16 | H25: =ROUNDUP('Sales forecast'!H$24/'Variable costs'!$C$12,0) -> 17 | I25: =ROUNDUP('Sales forecast'!I$24/'Variable costs'!$C$12,0) -> 18 | ... M25: =ROUNDUP('Sales forecast'!M$24/'Variable costs'!$C$12,0) -> 22
A26: =A11 -> Silver physical | B26: =ROUNDUP('Sales forecast'!B$25/'Variable costs'!$C$13,0) -> 42 | C26: =ROUNDUP('Sales forecast'!C$25/'Variable costs'!$C$13,0) -> 46 | D26: =ROUNDUP('Sales forecast'!D$25/'Variable costs'!$C$13,0) -> 50 | E26: =ROUNDUP('Sales forecast'!E$25/'Variable costs'!$C$13,0) -> 55 | F26: =ROUNDUP('Sales forecast'!F$25/'Variable costs'!$C$13,0) -> 59 | G26: =ROUNDUP('Sales forecast'!G$25/'Variable costs'!$C$13,0) -> 63 | H26: =ROUNDUP('Sales forecast'!H$25/'Variable costs'!$C$13,0) -> 67 | I26: =ROUNDUP('Sales forecast'!I$25/'Variable costs'!$C$13,0) -> 71 | ... M26: =ROUNDUP('Sales forecast'!M$25/'Variable costs'!$C$13,0) -> 88
A27: =A12 -> Gold physical | B27: =ROUNDUP('Sales forecast'!B$26/'Variable costs'!$C$14,0) -> 42 | C27: =ROUNDUP('Sales forecast'!C$26/'Variable costs'!$C$14,0) -> 46 | D27: =ROUNDUP('Sales forecast'!D$26/'Variable costs'!$C$14,0) -> 50 | E27: =ROUNDUP('Sales forecast'!E$26/'Variable costs'!$C$14,0) -> 55 | F27: =ROUNDUP('Sales forecast'!F$26/'Variable costs'!$C$14,0) -> 59 | G27: =ROUNDUP('Sales forecast'!G$26/'Variable costs'!$C$14,0) -> 63 | H27: =ROUNDUP('Sales forecast'!H$26/'Variable costs'!$C$14,0) -> 67 | I27: =ROUNDUP('Sales forecast'!I$26/'Variable costs'!$C$14,0) -> 71 | ... M27: =ROUNDUP('Sales forecast'!M$26/'Variable costs'!$C$14,0) -> 88
A28: =A13 -> Routers | B28: =ROUNDUP(SUM('Sales forecast'!B$24:B$26)/'Variable costs'!$C$15,0) -> 9 | C28: =ROUNDUP(SUM('Sales forecast'!C$24:C$26)/'Variable costs'!$C$15,0) -> 10 | D28: =ROUNDUP(SUM('Sales forecast'!D$24:D$26)/'Variable costs'!$C$15,0) -> 10 | E28: =ROUNDUP(SUM('Sales forecast'!E$24:E$26)/'Variable costs'!$C$15,0) -> 11 | F28: =ROUNDUP(SUM('Sales forecast'!F$24:F$26)/'Variable costs'!$C$15,0) -> 12 | G28: =ROUNDUP(SUM('Sales forecast'!G$24:G$26)/'Variable costs'!$C$15,0) -> 13 | H28: =ROUNDUP(SUM('Sales forecast'!H$24:H$26)/'Variable costs'!$C$15,0) -> 14 | I28: =ROUNDUP(SUM('Sales forecast'!I$24:I$26)/'Variable costs'!$C$15,0) -> 15 | ... M28: =ROUNDUP(SUM('Sales forecast'!M$24:M$26)/'Variable costs'!$C$15,0) -> 18
A29: =A14 -> Switches | B29: =ROUNDUP(SUM('Sales forecast'!B$24:B$26)/'Variable costs'!$C$16,0) -> 1 | C29: =ROUNDUP(SUM('Sales forecast'!C$24:C$26)/'Variable costs'!$C$16,0) -> 1 | D29: =ROUNDUP(SUM('Sales forecast'!D$24:D$26)/'Variable costs'!$C$16,0) -> 1 | E29: =ROUNDUP(SUM('Sales forecast'!E$24:E$26)/'Variable costs'!$C$16,0) -> 1 | F29: =ROUNDUP(SUM('Sales forecast'!F$24:F$26)/'Variable costs'!$C$16,0) -> 1 | G29: =ROUNDUP(SUM('Sales forecast'!G$24:G$26)/'Variable costs'!$C$16,0) -> 1 | H29: =ROUNDUP(SUM('Sales forecast'!H$24:H$26)/'Variable costs'!$C$16,0) -> 1 | I29: =ROUNDUP(SUM('Sales forecast'!I$24:I$26)/'Variable costs'!$C$16,0) -> 1 | ... M29: =ROUNDUP(SUM('Sales forecast'!M$24:M$26)/'Variable costs'!$C$16,0) -> 1

Sheet Expenses
A1: Total expenses
A9: Year 1 | B9: January | C9: February | D9: March | E9: April | F9: May | G9: June | H9: July | I9: August | J9: September | K9: October | L9: November | M9: December
A10: Bronze | B10: =('Hardware demands'!B10)*'Variable costs'!$E12 -> 1750 | C10: =('Hardware demands'!C10-'Hardware demands'!B10)*'Variable costs'!$E12 -> 0 | D10: =('Hardware demands'!D10-'Hardware demands'!C10)*'Variable costs'!$E12 -> 0 | E10: =('Hardware demands'!E10-'Hardware demands'!D10)*'Variable costs'!$E12 -> 1750 | F10: =('Hardware demands'!F10-'Hardware demands'!E10)*'Variable costs'!$E12 -> 0 | G10: =('Hardware demands'!G10-'Hardware demands'!F10)*'Variable costs'!$E12 -> 0 | H10: =('Hardware demands'!H10-'Hardware demands'!G10)*'Variable costs'!$E12 -> 0 | I10: =('Hardware demands'!I10-'Hardware demands'!H10)*'Variable costs'!$E12 -> 1750 | J10: =('Hardware demands'!J10-'Hardware demands'!I10)*'Variable costs'!$E12 -> 0 | ... M10: =('Hardware demands'!M10-'Hardware demands'!L10)*'Variable costs'!$E12 -> 1750
A11: Silver | B11: =('Hardware demands'!B11)*'Variable costs'!$E13 -> 3500 | C11: =('Hardware demands'!C11-'Hardware demands'!B11)*'Variable costs'!$E13 -> 1750 | D11: =('Hardware demands'!D11-'Hardware demands'!C11)*'Variable costs'!$E13 -> 1750 | E11: =('Hardware demands'!E11-'Hardware demands'!D11)*'Variable costs'!$E13 -> 1750 | F11: =('Hardware demands'!F11-'Hardware demands'!E11)*'Variable costs'!$E13 -> 1750 | G11: =('Hardware demands'!G11-'Hardware demands'!F11)*'Variable costs'!$E13 -> 1750 | H11: =('Hardware demands'!H11-'Hardware demands'!G11)*'Variable costs'!$E13 -> 1750 | I11: =('Hardware demands'!I11-'Hardware demands'!H11)*'Variable costs'!$E13 -> 1750 | J11: =('Hardware demands'!J11-'Hardware demands'!I11)*'Variable costs'!$E13 -> 1750 | ... M11: =('Hardware demands'!M11-'Hardware demands'!L11)*'Variable costs'!$E13 -> 1750
A12: Gold | B12: =('Hardware demands'!B12)*'Variable costs'!$E14 -> 3500 | C12: =('Hardware demands'!C12-'Hardware demands'!B12)*'Variable costs'!$E14 -> 1750 | D12: =('Hardware demands'!D12-'Hardware demands'!C12)*'Variable costs'!$E14 -> 1750 | E12: =('Hardware demands'!E12-'Hardware demands'!D12)*'Variable costs'!$E14 -> 1750 | F12: =('Hardware demands'!F12-'Hardware demands'!E12)*'Variable costs'!$E14 -> 1750 | G12: =('Hardware demands'!G12-'Hardware demands'!F12)*'Variable costs'!$E14 -> 1750 | H12: =('Hardware demands'!H12-'Hardware demands'!G12)*'Variable costs'!$E14 -> 1750 | I12: =('Hardware demands'!I12-'Hardware demands'!H12)*'Variable costs'!$E14 -> 1750 | J12: =('Hardware demands'!J12-'Hardware demands'!I12)*'Variable costs'!$E14 -> 1750 | ... M12: =('Hardware demands'!M12-'Hardware demands'!L12)*'Variable costs'!$E14 -> 1750
A13: Routers | B13: =('Hardware demands'!B13)*'Variable costs'!$E15 -> 3000 | C13: =('Hardware demands'!C13-'Hardware demands'!B13)*'Variable costs'!$E15 -> -1500 | D13: =('Hardware demands'!D13-'Hardware demands'!C13)*'Variable costs'!$E15 -> 0 | E13: =('Hardware demands'!E13-'Hardware demands'!D13)*'Variable costs'!$E15 -> 0 | F13: =('Hardware demands'!F13-'Hardware demands'!E13)*'Variable costs'!$E15 -> 1500 | G13: =('Hardware demands'!G13-'Hardware demands'!F13)*'Variable costs'!$E15 -> 0 | H13: =('Hardware demands'!H13-'Hardware demands'!G13)*'Variable costs'!$E15 -> 0 | I13: =('Hardware demands'!I13-'Hardware demands'!H13)*'Variable costs'!$E15 -> 0 | J13: =('Hardware demands'!J13-'Hardware demands'!I13)*'Variable costs'!$E15 -> 0 | ... M13: =('Hardware demands'!M13-'Hardware demands'!L13)*'Variable costs'!$E15 -> 0
A14: Switches | B14: =('Hardware demands'!B14)*'Variable costs'!$E16 -> 1000 | C14: =('Hardware demands'!C14-'Hardware demands'!B14)*'Variable costs'!$E16 -> 0 | D14: =('Hardware demands'!D14-'Hardware demands'!C14)*'Variable costs'!$E16 -> 0 | E14: =('Hardware demands'!E14-'Hardware demands'!D14)*'Variable costs'!$E16 -> 0 | F14: =('Hardware demands'!F14-'Hardware demands'!E14)*'Variable costs'!$E16 -> 0 | G14: =('Hardware demands'!G14-'Hardware demands'!F14)*'Variable costs'!$E16 -> 0 | H14: =('Hardware demands'!H14-'Hardware demands'!G14)*'Variable costs'!$E16 -> 0 | I14: =('Hardware demands'!I14-'Hardware demands'!H14)*'Variable costs'!$E16 -> 0 | J14: =('Hardware demands'!J14-'Hardware demands'!I14)*'Variable costs'!$E16 -> 0 | ... M14: =('Hardware demands'!M14-'Hardware demands'!L14)*'Variable costs'!$E16 -> 0
A15: Constant costs | B15: ='Constant costs'!D10 -> 2000 | C15: =0 -> 0 | D15: =0 -> 0 | E15: =0 -> 0 | F15: =0 -> 0 | G15: =0 -> 0 | H15: =0 -> 0 | I15: =0 -> 0 | J15: =0 -> 0 | ... M15: =0 -> 0
A16: Total costs | B16: =SUM(B10:B15) -> 14750 | C16: =SUM(C10:C15) -> 2000 | D16: =SUM(D10:D15) -> 3500 | E16: =SUM(E10:E15) -> 5250 | F16: =SUM(F10:F15) -> 5000 | G16: =SUM(G10:G15) -> 3500 | H16: =SUM(H10:H15) -> 3500 | I16: =SUM(I10:I15) -> 5250 | ... M16: =SUM(M10:M15) -> 5250
A18: Year 2 | B18: January | C18: February | D18: March | E18: April | F18: May | G18: June | H18: July | I18: August | J18: September | K18: October | L18: November | M18: December
A19: Bronze | B19: =('Hardware demands'!B18-'Hardware demands'!M10)*'Variable costs'!$E12 -> 0 | C19: =('Hardware demands'!C18-'Hardware demands'!B18)*'Variable costs'!$E12 -> 1750 | D19: =('Hardware demands'!D18-'Hardware demands'!C18)*'Variable costs'!$E12 -> 0 | E19: =('Hardware demands'!E18-'Hardware demands'!D18)*'Variable costs'!$E12 -> 1750 | F19: =('Hardware demands'!F18-'Hardware demands'!E18)*'Variable costs'!$E12 -> 0 | G19: =('Hardware demands'!G18-'Hardware demands'!F18)*'Variable costs'!$E12 -> 1750 | H19: =('Hardware demands'!H18-'Hardware demands'!G18)*'Variable costs'!$E12 -> 0 | I19: =('Hardware demands'!I18-'Hardware demands'!H18)*'Variable costs'!$E12 -> 1750 | J19: =('Hardware demands'!J18-'Hardware demands'!I18)*'Variable costs'!$E12 -> 0 | ... M19: =('Hardware demands'!M18-'Hardware demands'!L18)*'Variable costs'!$E12 -> 1750
A20: Silver | B20: =('Hardware demands'!B19-'Hardware demands'!M11)*'Variable costs'!$E13 -> 3500 | C20: =('Hardware demands'!C19-'Hardware demands'!B19)*'Variable costs'!$E13 -> 3500 | D20: =('Hardware demands'!D19-'Hardware demands'!C19)*'Variable costs'!$E13 -> 3500 | E20: =('Hardware demands'!E19-'Hardware demands'!D19)*'Variable costs'!$E13 -> 3500 | F20: =('Hardware demands'!F19-'Hardware demands'!E19)*'Variable costs'!$E13 -> 3500 | G20: =('Hardware demands'!G19-'Hardware demands'!F19)*'Variable costs'!$E13 -> 3500 | H20: =('Hardware demands'!H19-'Hardware demands'!G19)*'Variable costs'!$E13 -> 5250 | I20: =('Hardware demands'!I19-'Hardware demands'!H19)*'Variable costs'!$E13 -> 3500 | J20: =('Hardware demands'!J19-'Hardware demands'!I19)*'Variable costs'!$E13 -> 3500 | ... M20: =('Hardware demands'!M19-'Hardware demands'!L19)*'Variable costs'!$E13 -> 3500
A21: Gold | B21: =('Hardware demands'!B20-'Hardware demands'!M12)*'Variable costs'!$E14 -> 3500 | C21: =('Hardware demands'!C20-'Hardware demands'!B20)*'Variable costs'!$E14 -> 3500 | D21: =('Hardware demands'!D20-'Hardware demands'!C20)*'Variable costs'!$E14 -> 3500 | E21: =('Hardware demands'!E20-'Hardware demands'!D20)*'Variable costs'!$E14 -> 3500 | F21: =('Hardware demands'!F20-'Hardware demands'!E20)*'Variable costs'!$E14 -> 3500 | G21: =('Hardware demands'!G20-'Hardware demands'!F20)*'Variable costs'!$E14 -> 3500 | H21: =('Hardware demands'!H20-'Hardware demands'!G20)*'Variable costs'!$E14 -> 5250 | I21: =('Hardware demands'!I20-'Hardware demands'!H20)*'Variable costs'!$E14 -> 3500 | J21: =('Hardware demands'!J20-'Hardware demands'!I20)*'Variable costs'!$E14 -> 3500 | ... M21: =('Hardware demands'!M20-'Hardware demands'!L20)*'Variable costs'!$E14 -> 3500
A22: =A13 -> Routers | B22: =('Hardware demands'!B21-'Hardware demands'!M13)*'Variable costs'!$E15 -> 0 | C22: =('Hardware demands'!C21-'Hardware demands'!B21)*'Variable costs'!$E15 -> 1500 | D22: =('Hardware demands'!D21-'Hardware demands'!C21)*'Variable costs'!$E15 -> 0 | E22: =('Hardware demands'!E21-'Hardware demands'!D21)*'Variable costs'!$E15 -> 1500 | F22: =('Hardware demands'!F21-'Hardware demands'!E21)*'Variable costs'!$E15 -> 0 | G22: =('Hardware demands'!G21-'Hardware demands'!F21)*'Variable costs'!$E15 -> 0 | H22: =('Hardware demands'!H21-'Hardware demands'!G21)*'Variable costs'!$E15 -> 1500 | I22: =('Hardware demands'!I21-'Hardware demands'!H21)*'Variable costs'!$E15 -> 0 | J22: =('Hardware demands'!J21-'Hardware demands'!I21)*'Variable costs'!$E15 -> 1500 | ... M22: =('Hardware demands'!M21-'Hardware demands'!L21)*'Variable costs'!$E15 -> 0
A23: =A14 -> Switches | B23: =('Hardware demands'!B22-'Hardware demands'!M14)*'Variable costs'!$E16 -> 0 | C23: =('Hardware demands'!C22-'Hardware demands'!B22)*'Variable costs'!$E16 -> 0 | D23: =('Hardware demands'!D22-'Hardware demands'!C22)*'Variable costs'!$E16 -> 0 | E23: =('Hardware demands'!E22-'Hardware demands'!D22)*'Variable costs'!$E16 -> 0 | F23: =('Hardware demands'!F22-'Hardware demands'!E22)*'Variable costs'!$E16 -> 0 | G23: =('Hardware demands'!G22-'Hardware demands'!F22)*'Variable costs'!$E16 -> 0 | H23: =('Hardware demands'!H22-'Hardware demands'!G22)*'Variable costs'!$E16 -> 0 | I23: =('Hardware demands'!I22-'Hardware demands'!H22)*'Variable costs'!$E16 -> 0 | J23: =('Hardware demands'!J22-'Hardware demands'!I22)*'Variable costs'!$E16 -> 0 | ... M23: =('Hardware demands'!M22-'Hardware demands'!L22)*'Variable costs'!$E16 -> 0
A24: Constant costs | B24: =0 -> 0 | C24: =0 -> 0 | D24: =0 -> 0 | E24: =0 -> 0 | F24: =0 -> 0 | G24: =0 -> 0 | H24: =0 -> 0 | I24: =0 -> 0 | ... M24: =0 -> 0
A25: Total costs | B25: =SUM(B19:B24) -> 7000 | C25: =SUM(C19:C24) -> 10250 | D25: =SUM(D19:D24) -> 7000 | E25: =SUM(E19:E24) -> 10250 | F25: =SUM(F19:F24) -> 7000 | G25: =SUM(G19:G24) -> 8750 | H25: =SUM(H19:H24) -> 12000 | I25: =SUM(I19:I24) -> 8750 | ... M25: =SUM(M19:M24) -> 8750
A27: Year 3 | B27: January | C27: February | D27: March | E27: April | F27: May | G27: June | H27: July | I27: August | J27: September | K27: October | L27: November | M27: December
A28: Bronze | B28: =('Hardware demands'!B25-'Hardware demands'!M18)*'Variable costs'!$E12 -> 1750 | C28: =('Hardware demands'!C25-'Hardware demands'!B25)*'Variable costs'!$E12 -> 1750 | D28: =('Hardware demands'!D25-'Hardware demands'!C25)*'Variable costs'!$E12 -> 1750 | E28: =('Hardware demands'!E25-'Hardware demands'!D25)*'Variable costs'!$E12 -> 1750 | F28: =('Hardware demands'!F25-'Hardware demands'!E25)*'Variable costs'!$E12 -> 1750 | G28: =('Hardware demands'!G25-'Hardware demands'!F25)*'Variable costs'!$E12 -> 1750 | H28: =('Hardware demands'!H25-'Hardware demands'!G25)*'Variable costs'!$E12 -> 1750 | I28: =('Hardware demands'!I25-'Hardware demands'!H25)*'Variable costs'!$E12 -> 1750 | J28: =('Hardware demands'!J25-'Hardware demands'!I25)*'Variable costs'!$E12 -> 1750 | ... M28: =('Hardware demands'!M25-'Hardware demands'!L25)*'Variable costs'!$E12 -> 1750
A29: Silver | B29: =('Hardware demands'!B26-'Hardware demands'!M19)*'Variable costs'!$E13 -> 7000 | C29: =('Hardware demands'!C26-'Hardware demands'!B26)*'Variable costs'!$E13 -> 7000 | D29: =('Hardware demands'!D26-'Hardware demands'!C26)*'Variable costs'!$E13 -> 7000 | E29: =('Hardware demands'!E26-'Hardware demands'!D26)*'Variable costs'!$E13 -> 8750 | F29: =('Hardware demands'!F26-'Hardware demands'!E26)*'Variable costs'!$E13 -> 7000 | G29: =('Hardware demands'!G26-'Hardware demands'!F26)*'Variable costs'!$E13 -> 7000 | H29: =('Hardware demands'!H26-'Hardware demands'!G26)*'Variable costs'!$E13 -> 7000 | I29: =('Hardware demands'!I26-'Hardware demands'!H26)*'Variable costs'!$E13 -> 7000 | J29: =('Hardware demands'!J26-'Hardware demands'!I26)*'Variable costs'!$E13 -> 7000 | ... M29: =('Hardware demands'!M26-'Hardware demands'!L26)*'Variable costs'!$E13 -> 7000
A30: Gold | B30: =('Hardware demands'!B27-'Hardware demands'!M20)*'Variable costs'!$E14 -> 7000 | C30: =('Hardware demands'!C27-'Hardware demands'!B27)*'Variable costs'!$E14 -> 7000 | D30: =('Hardware demands'!D27-'Hardware demands'!C27)*'Variable costs'!$E14 -> 7000 | E30: =('Hardware demands'!E27-'Hardware demands'!D27)*'Variable costs'!$E14 -> 8750 | F30: =('Hardware demands'!F27-'Hardware demands'!E27)*'Variable costs'!$E14 -> 7000 | G30: =('Hardware demands'!G27-'Hardware demands'!F27)*'Variable costs'!$E14 -> 7000 | H30: =('Hardware demands'!H27-'Hardware demands'!G27)*'Variable costs'!$E14 -> 7000 | I30: =('Hardware demands'!I27-'Hardware demands'!H27)*'Variable costs'!$E14 -> 7000 | J30: =('Hardware demands'!J27-'Hardware demands'!I27)*'Variable costs'!$E14 -> 7000 | ... M30: =('Hardware demands'!M27-'Hardware demands'!L27)*'Variable costs'!$E14 -> 7000
A31: =A22 -> Routers | B31: =('Hardware demands'!B28-'Hardware demands'!M21)*'Variable costs'!$E15 -> 1500 | C31: =('Hardware demands'!C28-'Hardware demands'!B28)*'Variable costs'!$E15 -> 1500 | D31: =('Hardware demands'!D28-'Hardware demands'!C28)*'Variable costs'!$E15 -> 0 | E31: =('Hardware demands'!E28-'Hardware demands'!D28)*'Variable costs'!$E15 -> 1500 | F31: =('Hardware demands'!F28-'Hardware demands'!E28)*'Variable costs'!$E15 -> 1500 | G31: =('Hardware demands'!G28-'Hardware demands'!F28)*'Variable costs'!$E15 -> 1500 | H31: =('Hardware demands'!H28-'Hardware demands'!G28)*'Variable costs'!$E15 -> 1500 | I31: =('Hardware demands'!I28-'Hardware demands'!H28)*'Variable costs'!$E15 -> 1500 | J31: =('Hardware demands'!J28-'Hardware demands'!I28)*'Variable costs'!$E15 -> 0 | ... M31: =('Hardware demands'!M28-'Hardware demands'!L28)*'Variable costs'!$E15 -> 1500
A32: =A23 -> Switches | B32: =('Hardware demands'!B29-'Hardware demands'!M22)*'Variable costs'!$E16 -> 0 | C32: =('Hardware demands'!C29-'Hardware demands'!B29)*'Variable costs'!$E16 -> 0 | D32: =('Hardware demands'!D29-'Hardware demands'!C29)*'Variable costs'!$E16 -> 0 | E32: =('Hardware demands'!E29-'Hardware demands'!D29)*'Variable costs'!$E16 -> 0 | F32: =('Hardware demands'!F29-'Hardware demands'!E29)*'Variable costs'!$E16 -> 0 | G32: =('Hardware demands'!G29-'Hardware demands'!F29)*'Variable costs'!$E16 -> 0 | H32: =('Hardware demands'!H29-'Hardware demands'!G29)*'Variable costs'!$E16 -> 0 | I32: =('Hardware demands'!I29-'Hardware demands'!H29)*'Variable costs'!$E16 -> 0 | J32: =('Hardware demands'!J29-'Hardware demands'!I29)*'Variable costs'!$E16 -> 0 | ... M32: =('Hardware demands'!M29-'Hardware demands'!L29)*'Variable costs'!$E16 -> 0
A33: Constant costs | B33: =0 -> 0 | C33: =0 -> 0 | D33: =0 -> 0 | E33: =0 -> 0 | F33: =0 -> 0 | G33: =0 -> 0 | H33: =0 -> 0 | I33: =0 -> 0 | ... M33: =0 -> 0
A34: Total costs | B34: =SUM(B28:B33) -> 17250 | C34: =SUM(C28:C33) -> 17250 | D34: =SUM(D28:D33) -> 15750 | E34: =SUM(E28:E33) -> 20750 | F34: =SUM(F28:F33) -> 17250 | G34: =SUM(G28:G33) -> 17250 | H34: =SUM(H28:H33) -> 17250 | I34: =SUM(I28:I33) -> 17250 | ... M34: =SUM(M28:M33) -> 17250

Sheet Expenses2
A1: Total expenses
A9: Year 1 | B9: January | C9: February | D9: March | E9: April | F9: May | G9: June | H9: July | I9: August | J9: September | K9: October | L9: November | M9: December
A10: Bronze | B10: =('Hardware demands'!B10)*'Variable costs'!$E12 -> 1750 | C10: =('Hardware demands'!C10-'Hardware demands'!B10)*'Variable costs'!$E12 -> 0 | D10: =('Hardware demands'!D10-'Hardware demands'!C10)*'Variable costs'!$E12 -> 0 | E10: =('Hardware demands'!E10-'Hardware demands'!D10)*'Variable costs'!$E12 -> 1750 | F10: =('Hardware demands'!F10-'Hardware demands'!E10)*'Variable costs'!$E12 -> 0 | G10: =('Hardware demands'!G10-'Hardware demands'!F10)*'Variable costs'!$E12 -> 0 | H10: =('Hardware demands'!H10-'Hardware demands'!G10)*'Variable costs'!$E12 -> 0 | I10: =('Hardware demands'!I10-'Hardware demands'!H10)*'Variable costs'!$E12 -> 1750 | J10: =('Hardware demands'!J10-'Hardware demands'!I10)*'Variable costs'!$E12 -> 0 | ... M10: =('Hardware demands'!M10-'Hardware demands'!L10)*'Variable costs'!$E12 -> 1750
A11: Silver | B11: =('Hardware demands'!B11)*'Variable costs'!$E13 -> 3500 | C11: =('Hardware demands'!C11-'Hardware demands'!B11)*'Variable costs'!$E13 -> 1750 | D11: =('Hardware demands'!D11-'Hardware demands'!C11)*'Variable costs'!$E13 -> 1750 | E11: =('Hardware demands'!E11-'Hardware demands'!D11)*'Variable costs'!$E13 -> 1750 | F11: =('Hardware demands'!F11-'Hardware demands'!E11)*'Variable costs'!$E13 -> 1750 | G11: =('Hardware demands'!G11-'Hardware demands'!F11)*'Variable costs'!$E13 -> 1750 | H11: =('Hardware demands'!H11-'Hardware demands'!G11)*'Variable costs'!$E13 -> 1750 | I11: =('Hardware demands'!I11-'Hardware demands'!H11)*'Variable costs'!$E13 -> 1750 | J11: =('Hardware demands'!J11-'Hardware demands'!I11)*'Variable costs'!$E13 -> 1750 | ... M11: =('Hardware demands'!M11-'Hardware demands'!L11)*'Variable costs'!$E13 -> 1750
A12: Gold | B12: =('Hardware demands'!B12)*'Variable costs'!$E14 -> 3500 | C12: =('Hardware demands'!C12-'Hardware demands'!B12)*'Variable costs'!$E14 -> 1750 | D12: =('Hardware demands'!D12-'Hardware demands'!C12)*'Variable costs'!$E14 -> 1750 | E12: =('Hardware demands'!E12-'Hardware demands'!D12)*'Variable costs'!$E14 -> 1750 | F12: =('Hardware demands'!F12-'Hardware demands'!E12)*'Variable costs'!$E14 -> 1750 | G12: =('Hardware demands'!G12-'Hardware demands'!F12)*'Variable costs'!$E14 -> 1750 | H12: =('Hardware demands'!H12-'Hardware demands'!G12)*'Variable costs'!$E14 -> 1750 | I12: =('Hardware demands'!I12-'Hardware demands'!H12)*'Variable costs'!$E14 -> 1750 | J12: =('Hardware demands'!J12-'Hardware demands'!I12)*'Variable costs'!$E14 -> 1750 | ... M12: =('Hardware demands'!M12-'Hardware demands'!L12)*'Variable costs'!$E14 -> 1750
A13: Routers | B13: =('Hardware demands'!B13)*'Variable costs'!$E15 -> 3000 | C13: =('Hardware demands'!C13-'Hardware demands'!B13)*'Variable costs'!$E15 -> -1500 | D13: =('Hardware demands'!D13-'Hardware demands'!C13)*'Variable costs'!$E15 -> 0 | E13: =('Hardware demands'!E13-'Hardware demands'!D13)*'Variable costs'!$E15 -> 0 | F13: =('Hardware demands'!F13-'Hardware demands'!E13)*'Variable costs'!$E15 -> 1500 | G13: =('Hardware demands'!G13-'Hardware demands'!F13)*'Variable costs'!$E15 -> 0 | H13: =('Hardware demands'!H13-'Hardware demands'!G13)*'Variable costs'!$E15 -> 0 | I13: =('Hardware demands'!I13-'Hardware demands'!H13)*'Variable costs'!$E15 -> 0 | J13: =('Hardware demands'!J13-'Hardware demands'!I13)*'Variable costs'!$E15 -> 0 | ... M13: =('Hardware demands'!M13-'Hardware demands'!L13)*'Variable costs'!$E15 -> 0
A14: Switches | B14: =('Hardware demands'!B14)*'Variable costs'!$E16 -> 1000 | C14: =('Hardware demands'!C14-'Hardware demands'!B14)*'Variable costs'!$E16 -> 0 | D14: =('Hardware demands'!D14-'Hardware demands'!C14)*'Variable costs'!$E16 -> 0 | E14: =('Hardware demands'!E14-'Hardware demands'!D14)*'Variable costs'!$E16 -> 0 | F14: =('Hardware demands'!F14-'Hardware demands'!E14)*'Variable costs'!$E16 -> 0 | G14: =('Hardware demands'!G14-'Hardware demands'!F14)*'Variable costs'!$E16 -> 0 | H14: =('Hardware demands'!H14-'Hardware demands'!G14)*'Variable costs'!$E16 -> 0 | I14: =('Hardware demands'!I14-'Hardware demands'!H14)*'Variable costs'!$E16 -> 0 | J14: =('Hardware demands'!J14-'Hardware demands'!I14)*'Variable costs'!$E16 -> 0 | ... M14: =('Hardware demands'!M14-'Hardware demands'!L14)*'Variable costs'!$E16 -> 0
A15: Constant costs | B15: =Expenses!B15 -> 2000 | C15: =Expenses!C15 -> 0 | D15: =Expenses!D15 -> 0 | E15: =Expenses!E15 -> 0 | F15: =Expenses!F15 -> 0 | G15: =Expenses!G15 -> 0 | H15: =Expenses!H15 -> 0 | I15: =Expenses!I15 -> 0 | ... M15: =Expenses!M15 -> 0
A16: Total costs | B16: =SUM(B10:B15) -> 14750 | C16: =SUM(C10:C15)+B16 -> 16750 | D16: =SUM(D10:D15)+C16 -> 20250 | E16: =SUM(E10:E15)+D16 -> 25500 | F16: =SUM(F10:F15)+E16 -> 30500 | G16: =SUM(G10:G15)+F16 -> 34000 | H16: =SUM(H10:H15)+G16 -> 37500 | I16: =SUM(I10:I15)+H16 -> 42750 | J16: =SUM(J10:J15)+I16 -> 46250 | ... M16: =SUM(M10:M15)+L16 -> 60000
A18: Year 2 | B18: January | C18: February | D18: March | E18: April | F18: May | G18: June | H18: July | I18: August | J18: September | K18: October | L18: November | M18: December
A19: Bronze | B19: =('Hardware demands'!B18-'Hardware demands'!M10)*'Variable costs'!$E12 -> 0 | C19: =('Hardware demands'!C18-'Hardware demands'!B18)*'Variable costs'!$E12 -> 1750 | D19: =('Hardware demands'!D18-'Hardware demands'!C18)*'Variable costs'!$E12 -> 0 | E19: =('Hardware demands'!E18-'Hardware demands'!D18)*'Variable costs'!$E12 -> 1750 | F19: =('Hardware demands'!F18-'Hardware demands'!E18)*'Variable costs'!$E12 -> 0 | G19: =('Hardware demands'!G18-'Hardware demands'!F18)*'Variable costs'!$E12 -> 1750 | H19: =('Hardware demands'!H18-'Hardware demands'!G18)*'Variable costs'!$E12 -> 0 | I19: =('Hardware demands'!I18-'Hardware demands'!H18)*'Variable costs'!$E12 -> 1750 | J19: =('Hardware demands'!J18-'Hardware demands'!I18)*'Variable costs'!$E12 -> 0 | ... M19: =('Hardware demands'!M18-'Hardware demands'!L18)*'Variable costs'!$E12 -> 1750
A20: Silver | B20: =('Hardware demands'!B19-'Hardware demands'!M11)*'Variable costs'!$E13 -> 3500 | C20: =('Hardware demands'!C19-'Hardware demands'!B19)*'Variable costs'!$E13 -> 3500 | D20: =('Hardware demands'!D19-'Hardware demands'!C19)*'Variable costs'!$E13 -> 3500 | E20: =('Hardware demands'!E19-'Hardware demands'!D19)*'Variable costs'!$E13 -> 3500 | F20: =('Hardware demands'!F19-'Hardware demands'!E19)*'Variable costs'!$E13 -> 3500 | G20: =('Hardware demands'!G19-'Hardware demands'!F19)*'Variable costs'!$E13 -> 3500 | H20: =('Hardware demands'!H19-'Hardware demands'!G19)*'Variable costs'!$E13 -> 5250 | I20: =('Hardware demands'!I19-'Hardware demands'!H19)*'Variable costs'!$E13 -> 3500 | J20: =('Hardware demands'!J19-'Hardware demands'!I19)*'Variable costs'!$E13 -> 3500 | ... M20: =('Hardware demands'!M19-'Hardware demands'!L19)*'Variable costs'!$E13 -> 3500
A21: Gold | B21: =('Hardware demands'!B20-'Hardware demands'!M12)*'Variable costs'!$E14 -> 3500 | C21: =('Hardware demands'!C20-'Hardware demands'!B20)*'Variable costs'!$E14 -> 3500 | D21: =('Hardware demands'!D20-'Hardware demands'!C20)*'Variable costs'!$E14 -> 3500 | E21: =('Hardware demands'!E20-'Hardware demands'!D20)*'Variable costs'!$E14 -> 3500 | F21: =('Hardware demands'!F20-'Hardware demands'!E20)*'Variable costs'!$E14 -> 3500 | G21: =('Hardware demands'!G20-'Hardware demands'!F20)*'Variable costs'!$E14 -> 3500 | H21: =('Hardware demands'!H20-'Hardware demands'!G20)*'Variable costs'!$E14 -> 5250 | I21: =('Hardware demands'!I20-'Hardware demands'!H20)*'Variable costs'!$E14 -> 3500 | J21: =('Hardware demands'!J20-'Hardware demands'!I20)*'Variable costs'!$E14 -> 3500 | ... M21: =('Hardware demands'!M20-'Hardware demands'!L20)*'Variable costs'!$E14 -> 3500
A22: =A13 -> Routers | B22: =('Hardware demands'!B21-'Hardware demands'!M13)*'Variable costs'!$E15 -> 0 | C22: =('Hardware demands'!C21-'Hardware demands'!B21)*'Variable costs'!$E15 -> 1500 | D22: =('Hardware demands'!D21-'Hardware demands'!C21)*'Variable costs'!$E15 -> 0 | E22: =('Hardware demands'!E21-'Hardware demands'!D21)*'Variable costs'!$E15 -> 1500 | F22: =('Hardware demands'!F21-'Hardware demands'!E21)*'Variable costs'!$E15 -> 0 | G22: =('Hardware demands'!G21-'Hardware demands'!F21)*'Variable costs'!$E15 -> 0 | H22: =('Hardware demands'!H21-'Hardware demands'!G21)*'Variable costs'!$E15 -> 1500 | I22: =('Hardware demands'!I21-'Hardware demands'!H21)*'Variable costs'!$E15 -> 0 | J22: =('Hardware demands'!J21-'Hardware demands'!I21)*'Variable costs'!$E15 -> 1500 | ... M22: =('Hardware demands'!M21-'Hardware demands'!L21)*'Variable costs'!$E15 -> 0
A23: =A14 -> Switches | B23: =('Hardware demands'!B22-'Hardware demands'!M14)*'Variable costs'!$E16 -> 0 | C23: =('Hardware demands'!C22-'Hardware demands'!B22)*'Variable costs'!$E16 -> 0 | D23: =('Hardware demands'!D22-'Hardware demands'!C22)*'Variable costs'!$E16 -> 0 | E23: =('Hardware demands'!E22-'Hardware demands'!D22)*'Variable costs'!$E16 -> 0 | F23: =('Hardware demands'!F22-'Hardware demands'!E22)*'Variable costs'!$E16 -> 0 | G23: =('Hardware demands'!G22-'Hardware demands'!F22)*'Variable costs'!$E16 -> 0 | H23: =('Hardware demands'!H22-'Hardware demands'!G22)*'Variable costs'!$E16 -> 0 | I23: =('Hardware demands'!I22-'Hardware demands'!H22)*'Variable costs'!$E16 -> 0 | J23: =('Hardware demands'!J22-'Hardware demands'!I22)*'Variable costs'!$E16 -> 0 | ... M23: =('Hardware demands'!M22-'Hardware demands'!L22)*'Variable costs'!$E16 -> 0
A24: Constant costs | B24: =Expenses!B24 -> 0 | C24: =Expenses!C24 -> 0 | D24: =Expenses!D24 -> 0 | E24: =Expenses!E24 -> 0 | F24: =Expenses!F24 -> 0 | G24: =Expenses!G24 -> 0 | H24: =Expenses!H24 -> 0 | I24: =Expenses!I24 -> 0 | ... M24: =Expenses!M24 -> 0
A25: Total costs | B25: =SUM(B19:B24)+M16 -> 67000 | C25: =SUM(C19:C24)+B25 -> 77250 | D25: =SUM(D19:D24)+C25 -> 84250 | E25: =SUM(E19:E24)+D25 -> 94500 | F25: =SUM(F19:F24)+E25 -> 101500 | G25: =SUM(G19:G24)+F25 -> 110250 | H25: =SUM(H19:H24)+G25 -> 122250 | I25: =SUM(I19:I24)+H25 -> 131000 | J25: =SUM(J19:J24)+I25 -> 139500 | ... M25: =SUM(M19:M24)+L25 -> 165500
A27: Year 3 | B27: January | C27: February | D27: March | E27: April | F27: May | G27: June | H27: July | I27: August | J27: September | K27: October | L27: November | M27: December
A28: Bronze | B28: =('Hardware demands'!B25-'Hardware demands'!M18)*'Variable costs'!$E12 -> 1750 | C28: =('Hardware demands'!C25-'Hardware demands'!B25)*'Variable costs'!$E12 -> 1750 | D28: =('Hardware demands'!D25-'Hardware demands'!C25)*'Variable costs'!$E12 -> 1750 | E28: =('Hardware demands'!E25-'Hardware demands'!D25)*'Variable costs'!$E12 -> 1750 | F28: =('Hardware demands'!F25-'Hardware demands'!E25)*'Variable costs'!$E12 -> 1750 | G28: =('Hardware demands'!G25-'Hardware demands'!F25)*'Variable costs'!$E12 -> 1750 | H28: =('Hardware demands'!H25-'Hardware demands'!G25)*'Variable costs'!$E12 -> 1750 | I28: =('Hardware demands'!I25-'Hardware demands'!H25)*'Variable costs'!$E12 -> 1750 | J28: =('Hardware demands'!J25-'Hardware demands'!I25)*'Variable costs'!$E12 -> 1750 | ... M28: =('Hardware demands'!M25-'Hardware demands'!L25)*'Variable costs'!$E12 -> 1750
A29: Silver | B29: =('Hardware demands'!B26-'Hardware demands'!M19)*'Variable costs'!$E13 -> 7000 | C29: =('Hardware demands'!C26-'Hardware demands'!B26)*'Variable costs'!$E13 -> 7000 | D29: =('Hardware demands'!D26-'Hardware demands'!C26)*'Variable costs'!$E13 -> 7000 | E29: =('Hardware demands'!E26-'Hardware demands'!D26)*'Variable costs'!$E13 -> 8750 | F29: =('Hardware demands'!F26-'Hardware demands'!E26)*'Variable costs'!$E13 -> 7000 | G29: =('Hardware demands'!G26-'Hardware demands'!F26)*'Variable costs'!$E13 -> 7000 | H29: =('Hardware demands'!H26-'Hardware demands'!G26)*'Variable costs'!$E13 -> 7000 | I29: =('Hardware demands'!I26-'Hardware demands'!H26)*'Variable costs'!$E13 -> 7000 | J29: =('Hardware demands'!J26-'Hardware demands'!I26)*'Variable costs'!$E13 -> 7000 | ... M29: =('Hardware demands'!M26-'Hardware demands'!L26)*'Variable costs'!$E13 -> 7000
A30: Gold | B30: =('Hardware demands'!B27-'Hardware demands'!M20)*'Variable costs'!$E14 -> 7000 | C30: =('Hardware demands'!C27-'Hardware demands'!B27)*'Variable costs'!$E14 -> 7000 | D30: =('Hardware demands'!D27-'Hardware demands'!C27)*'Variable costs'!$E14 -> 7000 | E30: =('Hardware demands'!E27-'Hardware demands'!D27)*'Variable costs'!$E14 -> 8750 | F30: =('Hardware demands'!F27-'Hardware demands'!E27)*'Variable costs'!$E14 -> 7000 | G30: =('Hardware demands'!G27-'Hardware demands'!F27)*'Variable costs'!$E14 -> 7000 | H30: =('Hardware demands'!H27-'Hardware demands'!G27)*'Variable costs'!$E14 -> 7000 | I30: =('Hardware demands'!I27-'Hardware demands'!H27)*'Variable costs'!$E14 -> 7000 | J30: =('Hardware demands'!J27-'Hardware demands'!I27)*'Variable costs'!$E14 -> 7000 | ... M30: =('Hardware demands'!M27-'Hardware demands'!L27)*'Variable costs'!$E14 -> 7000
A31: =A22 -> Routers | B31: =('Hardware demands'!B28-'Hardware demands'!M21)*'Variable costs'!$E15 -> 1500 | C31: =('Hardware demands'!C28-'Hardware demands'!B28)*'Variable costs'!$E15 -> 1500 | D31: =('Hardware demands'!D28-'Hardware demands'!C28)*'Variable costs'!$E15 -> 0 | E31: =('Hardware demands'!E28-'Hardware demands'!D28)*'Variable costs'!$E15 -> 1500 | F31: =('Hardware demands'!F28-'Hardware demands'!E28)*'Variable costs'!$E15 -> 1500 | G31: =('Hardware demands'!G28-'Hardware demands'!F28)*'Variable costs'!$E15 -> 1500 | H31: =('Hardware demands'!H28-'Hardware demands'!G28)*'Variable costs'!$E15 -> 1500 | I31: =('Hardware demands'!I28-'Hardware demands'!H28)*'Variable costs'!$E15 -> 1500 | J31: =('Hardware demands'!J28-'Hardware demands'!I28)*'Variable costs'!$E15 -> 0 | ... M31: =('Hardware demands'!M28-'Hardware demands'!L28)*'Variable costs'!$E15 -> 1500
A32: =A23 -> Switches | B32: =('Hardware demands'!B29-'Hardware demands'!M22)*'Variable costs'!$E16 -> 0 | C32: =('Hardware demands'!C29-'Hardware demands'!B29)*'Variable costs'!$E16 -> 0 | D32: =('Hardware demands'!D29-'Hardware demands'!C29)*'Variable costs'!$E16 -> 0 | E32: =('Hardware demands'!E29-'Hardware demands'!D29)*'Variable costs'!$E16 -> 0 | F32: =('Hardware demands'!F29-'Hardware demands'!E29)*'Variable costs'!$E16 -> 0 | G32: =('Hardware demands'!G29-'Hardware demands'!F29)*'Variable costs'!$E16 -> 0 | H32: =('Hardware demands'!H29-'Hardware demands'!G29)*'Variable costs'!$E16 -> 0 | I32: =('Hardware demands'!I29-'Hardware demands'!H29)*'Variable costs'!$E16 -> 0 | J32: =('Hardware demands'!J29-'Hardware demands'!I29)*'Variable costs'!$E16 -> 0 | ... M32: =('Hardware demands'!M29-'Hardware demands'!L29)*'Variable costs'!$E16 -> 0
A33: Constant costs | B33: =Expenses!B33 -> 0 | C33: =Expenses!C33 -> 0 | D33: =Expenses!D33 -> 0 | E33: =Expenses!E33 -> 0 | F33: =Expenses!F33 -> 0 | G33: =Expenses!G33 -> 0 | H33: =Expenses!H33 -> 0 | I33: =Expenses!I33 -> 0 | ... M33: =Expenses!M33 -> 0
A34: Total costs | B34: =SUM(B28:B33)+M25 -> 182750 | C34: =SUM(C28:C33)+B34 -> 200000 | D34: =SUM(D28:D33)+C34 -> 215750 | E34: =SUM(E28:E33)+D34 -> 236500 | F34: =SUM(F28:F33)+E34 -> 253750 | G34: =SUM(G28:G33)+F34 -> 271000 | H34: =SUM(H28:H33)+G34 -> 288250 | I34: =SUM(I28:I33)+H34 -> 305500 | J34: =SUM(J28:J33)+I34 -> 321250 | ... M34: =SUM(M28:M33)+L34 -> 376500

Sheet Total costs
A1: Total costs
A9: Year 1 | B9: January | C9: February | D9: March | E9: April | F9: May | G9: June | H9: July | I9: August | J9: September | K9: October | L9: November | M9: December
A10: Bronze | B10: =('Hardware demands'!B10)*'Variable costs'!$I12 -> 0.24305556 | C10: =('Hardware demands'!C10)*'Variable costs'!$I12 -> 0.24305556 | D10: =('Hardware demands'!D10)*'Variable costs'!$I12 -> 0.24305556 | E10: =('Hardware demands'!E10)*'Variable costs'!$I12 -> 0.48611111 | F10: =('Hardware demands'!F10)*'Variable costs'!$I12 -> 0.48611111 | G10: =('Hardware demands'!G10)*'Variable costs'!$I12 -> 0.48611111 | H10: =('Hardware demands'!H10)*'Variable costs'!$I12 -> 0.48611111 | I10: =('Hardware demands'!I10)*'Variable costs'!$I12 -> 0.72916667 | ... M10: =('Hardware demands'!M10)*'Variable costs'!$I12 -> 0.97222222
A11: Silver | B11: =('Hardware demands'!B11)*'Variable costs'!$I13 -> 0.97222222 | C11: =('Hardware demands'!C11)*'Variable costs'!$I13 -> 1.4583333 | D11: =('Hardware demands'!D11)*'Variable costs'!$I13 -> 1.9444444 | E11: =('Hardware demands'!E11)*'Variable costs'!$I13 -> 2.4305556 | F11: =('Hardware demands'!F11)*'Variable costs'!$I13 -> 2.9166667 | G11: =('Hardware demands'!G11)*'Variable costs'!$I13 -> 3.4027778 | H11: =('Hardware demands'!H11)*'Variable costs'!$I13 -> 3.8888889 | I11: =('Hardware demands'!I11)*'Variable costs'!$I13 -> 4.375 | ... M11: =('Hardware demands'!M11)*'Variable costs'!$I13 -> 6.3194444
A12: Gold | B12: =('Hardware demands'!B12)*'Variable costs'!$I14 -> 1.9444444 | C12: =('Hardware demands'!C12)*'Variable costs'!$I14 -> 2.9166667 | D12: =('Hardware demands'!D12)*'Variable costs'!$I14 -> 3.8888889 | E12: =('Hardware demands'!E12)*'Variable costs'!$I14 -> 4.8611111 | F12: =('Hardware demands'!F12)*'Variable costs'!$I14 -> 5.8333333 | G12: =('Hardware demands'!G12)*'Variable costs'!$I14 -> 6.8055556 | H12: =('Hardware demands'!H12)*'Variable costs'!$I14 -> 7.7777778 | I12: =('Hardware demands'!I12)*'Variable costs'!$I14 -> 8.75 | ... M12: =('Hardware demands'!M12)*'Variable costs'!$I14 -> 12.638889
A13: Routers | B13: =('Hardware demands'!B13)*'Variable costs'!$I15 -> 0.083333333 | C13: =('Hardware demands'!C13)*'Variable costs'!$I15 -> 0.041666667 | D13: =('Hardware demands'!D13)*'Variable costs'!$I15 -> 0.041666667 | E13: =('Hardware demands'!E13)*'Variable costs'!$I15 -> 0.041666667 | F13: =('Hardware demands'!F13)*'Variable costs'!$I15 -> 0.083333333 | G13: =('Hardware demands'!G13)*'Variable costs'!$I15 -> 0.083333333 | H13: =('Hardware demands'!H13)*'Variable costs'!$I15 -> 0.083333333 | I13: =('Hardware demands'!I13)*'Variable costs'!$I15 -> 0.083333333 | ... M13: =('Hardware demands'!M13)*'Variable costs'!$I15 -> 0.125
A14: Switches | B14: =('Hardware demands'!B14)*'Variable costs'!$I16 -> 0.00092592593 | C14: =('Hardware demands'!C14)*'Variable costs'!$I16 -> 0.00092592593 | D14: =('Hardware demands'!D14)*'Variable costs'!$I16 -> 0.00092592593 | E14: =('Hardware demands'!E14)*'Variable costs'!$I16 -> 0.00092592593 | F14: =('Hardware demands'!F14)*'Variable costs'!$I16 -> 0.00092592593 | G14: =('Hardware demands'!G14)*'Variable costs'!$I16 -> 0.00092592593 | H14: =('Hardware demands'!H14)*'Variable costs'!$I16 -> 0.00092592593 | I14: =('Hardware demands'!I14)*'Variable costs'!$I16 -> 0.00092592593 | ... M14: =('Hardware demands'!M14)*'Variable costs'!$I16 -> 0.00092592593
A15: Constant costs | B15: ='Constant costs'!$B$26 -> 55.555556 | C15: ='Constant costs'!$B$26 -> 55.555556 | D15: ='Constant costs'!$B$26 -> 55.555556 | E15: ='Constant costs'!$B$26 -> 55.555556 | F15: ='Constant costs'!$B$26 -> 55.555556 | G15: ='Constant costs'!$B$26 -> 55.555556 | H15: ='Constant costs'!$B$26 -> 55.555556 | I15: ='Constant costs'!$B$26 -> 55.555556 | ... M15: ='Constant costs'!$B$26 -> 55.555556
A16: Total costs | B16: =SUM(B10:B15) -> 58.799537 | C16: =SUM(C10:C15) -> 60.216204 | D16: =SUM(D10:D15) -> 61.674537 | E16: =SUM(E10:E15) -> 63.375926 | F16: =SUM(F10:F15) -> 64.875926 | G16: =SUM(G10:G15) -> 66.334259 | H16: =SUM(H10:H15) -> 67.792593 | I16: =SUM(I10:I15) -> 69.493981 | ... M16: =SUM(M10:M15) -> 75.612037
A18: Year 2 | B18: January | C18: February | D18: March | E18: April | F18: May | G18: June | H18: July | I18: August | J18: September | K18: October | L18: November | M18: December
A19: Bronze | B19: ='Hardware demands'!B18*'Variable costs'!$I12 -> 0.97222222 | C19: ='Hardware demands'!C18*'Variable costs'!$I12 -> 1.2152778 | D19: ='Hardware demands'!D18*'Variable costs'!$I12 -> 1.2152778 | E19: ='Hardware demands'!E18*'Variable costs'!$I12 -> 1.4583333 | F19: ='Hardware demands'!F18*'Variable costs'!$I12 -> 1.4583333 | G19: ='Hardware demands'!G18*'Variable costs'!$I12 -> 1.7013889 | H19: ='Hardware demands'!H18*'Variable costs'!$I12 -> 1.7013889 | I19: ='Hardware demands'!I18*'Variable costs'!$I12 -> 1.9444444 | ... M19: ='Hardware demands'!M18*'Variable costs'!$I12 -> 2.4305556
A20: Silver | B20: ='Hardware demands'!B19*'Variable costs'!$I13 -> 7.2916667 | C20: ='Hardware demands'!C19*'Variable costs'!$I13 -> 8.2638889 | D20: ='Hardware demands'!D19*'Variable costs'!$I13 -> 9.2361111 | E20: ='Hardware demands'!E19*'Variable costs'!$I13 -> 10.208333 | F20: ='Hardware demands'!F19*'Variable costs'!$I13 -> 11.180556 | G20: ='Hardware demands'!G19*'Variable costs'!$I13 -> 12.152778 | H20: ='Hardware demands'!H19*'Variable costs'!$I13 -> 13.611111 | I20: ='Hardware demands'!I19*'Variable costs'!$I13 -> 14.583333 | ... M20: ='Hardware demands'!M19*'Variable costs'!$I13 -> 18.472222
A21: Gold | B21: ='Hardware demands'!B20*'Variable costs'!$I14 -> 14.583333 | C21: ='Hardware demands'!C20*'Variable costs'!$I14 -> 16.527778 | D21: ='Hardware demands'!D20*'Variable costs'!$I14 -> 18.472222 | E21: ='Hardware demands'!E20*'Variable costs'!$I14 -> 20.416667 | F21: ='Hardware demands'!F20*'Variable costs'!$I14 -> 22.361111 | G21: ='Hardware demands'!G20*'Variable costs'!$I14 -> 24.305556 | H21: ='Hardware demands'!H20*'Variable costs'!$I14 -> 27.222222 | I21: ='Hardware demands'!I20*'Variable costs'!$I14 -> 29.166667 | ... M21: ='Hardware demands'!M20*'Variable costs'!$I14 -> 36.944444
A22: =A13 -> Routers | B22: ='Hardware demands'!B21*'Variable costs'!$I15 -> 0.125 | C22: ='Hardware demands'!C21*'Variable costs'!$I15 -> 0.16666667 | D22: ='Hardware demands'!D21*'Variable costs'!$I15 -> 0.16666667 | E22: ='Hardware demands'!E21*'Variable costs'!$I15 -> 0.20833333 | F22: ='Hardware demands'!F21*'Variable costs'!$I15 -> 0.20833333 | G22: ='Hardware demands'!G21*'Variable costs'!$I15 -> 0.20833333 | H22: ='Hardware demands'!H21*'Variable costs'!$I15 -> 0.25 | I22: ='Hardware demands'!I21*'Variable costs'!$I15 -> 0.25 | ... M22: ='Hardware demands'!M21*'Variable costs'!$I15 -> 0.33333333
A23: =A14 -> Switches | B23: ='Hardware demands'!B22*'Variable costs'!$I16 -> 0.00092592593 | C23: ='Hardware demands'!C22*'Variable costs'!$I16 -> 0.00092592593 | D23: ='Hardware demands'!D22*'Variable costs'!$I16 -> 0.00092592593 | E23: ='Hardware demands'!E22*'Variable costs'!$I16 -> 0.00092592593 | F23: ='Hardware demands'!F22*'Variable costs'!$I16 -> 0.00092592593 | G23: ='Hardware demands'!G22*'Variable costs'!$I16 -> 0.00092592593 | H23: ='Hardware demands'!H22*'Variable costs'!$I16 -> 0.00092592593 | I23: ='Hardware demands'!I22*'Variable costs'!$I16 -> 0.00092592593 | ... M23: ='Hardware demands'!M22*'Variable costs'!$I16 -> 0.00092592593
A24: Constant costs | B24: ='Constant costs'!$B$26 -> 55.555556 | C24: ='Constant costs'!$B$26 -> 55.555556 | D24: ='Constant costs'!$B$26 -> 55.555556 | E24: ='Constant costs'!$B$26 -> 55.555556 | F24: ='Constant costs'!$B$26 -> 55.555556 | G24: ='Constant costs'!$B$26 -> 55.555556 | H24: ='Constant costs'!$B$26 -> 55.555556 | I24: ='Constant costs'!$B$26 -> 55.555556 | ... M24: ='Constant costs'!$B$26 -> 55.555556
A25: Total costs | B25: =SUM(B19:B24) -> 78.528704 | C25: =SUM(C19:C24) -> 81.730093 | D25: =SUM(D19:D24) -> 84.646759 | E25: =SUM(E19:E24) -> 87.848148 | F25: =SUM(F19:F24) -> 90.764815 | G25: =SUM(G19:G24) -> 93.924537 | H25: =SUM(H19:H24) -> 98.341204 | I25: =SUM(I19:I24) -> 101.50093 | ... M25: =SUM(M19:M24) -> 113.73704
A27: Year 3 | B27: January | C27: February | D27: March | E27: April | F27: May | G27: June | H27: July | I27: August | J27: September | K27: October | L27: November | M27: December
A28: Bronze | B28: ='Hardware demands'!B25*'Variable costs'!$I12 -> 2.6736111 | C28: ='Hardware demands'!C25*'Variable costs'!$I12 -> 2.9166667 | D28: ='Hardware demands'!D25*'Variable costs'!$I12 -> 3.1597222 | E28: ='Hardware demands'!E25*'Variable costs'!$I12 -> 3.4027778 | F28: ='Hardware demands'!F25*'Variable costs'!$I12 -> 3.6458333 | G28: ='Hardware demands'!G25*'Variable costs'!$I12 -> 3.8888889 | H28: ='Hardware demands'!H25*'Variable costs'!$I12 -> 4.1319444 | I28: ='Hardware demands'!I25*'Variable costs'!$I12 -> 4.375 | ... M28: ='Hardware demands'!M25*'Variable costs'!$I12 -> 5.3472222
A29: Silver | B29: ='Hardware demands'!B26*'Variable costs'!$I13 -> 20.416667 | C29: ='Hardware demands'!C26*'Variable costs'!$I13 -> 22.361111 | D29: ='Hardware demands'!D26*'Variable costs'!$I13 -> 24.305556 | E29: ='Hardware demands'!E26*'Variable costs'!$I13 -> 26.736111 | F29: ='Hardware demands'!F26*'Variable costs'!$I13 -> 28.680556 | G29: ='Hardware demands'!G26*'Variable costs'!$I13 -> 30.625 | H29: ='Hardware demands'!H26*'Variable costs'!$I13 -> 32.569444 | I29: ='Hardware demands'!I26*'Variable costs'!$I13 -> 34.513889 | ... M29: ='Hardware demands'!M26*'Variable costs'!$I13 -> 42.777778
A30: Gold | B30: ='Hardware demands'!B27*'Variable costs'!$I14 -> 40.833333 | C30: ='Hardware demands'!C27*'Variable costs'!$I14 -> 44.722222 | D30: ='Hardware demands'!D27*'Variable costs'!$I14 -> 48.611111 | E30: ='Hardware demands'!E27*'Variable costs'!$I14 -> 53.472222 | F30: ='Hardware demands'!F27*'Variable costs'!$I14 -> 57.361111 | G30: ='Hardware demands'!G27*'Variable costs'!$I14 -> 61.25 | H30: ='Hardware demands'!H27*'Variable costs'!$I14 -> 65.138889 | I30: ='Hardware demands'!I27*'Variable costs'!$I14 -> 69.027778 | ... M30: ='Hardware demands'!M27*'Variable costs'!$I14 -> 85.555556
A31: =A22 -> Routers | B31: ='Hardware demands'!B28*'Variable costs'!$I15 -> 0.375 | C31: ='Hardware demands'!C28*'Variable costs'!$I15 -> 0.41666667 | D31: ='Hardware demands'!D28*'Variable costs'!$I15 -> 0.41666667 | E31: ='Hardware demands'!E28*'Variable costs'!$I15 -> 0.45833333 | F31: ='Hardware demands'!F28*'Variable costs'!$I15 -> 0.5 | G31: ='Hardware demands'!G28*'Variable costs'!$I15 -> 0.54166667 | H31: ='Hardware demands'!H28*'Variable costs'!$I15 -> 0.58333333 | I31: ='Hardware demands'!I28*'Variable costs'!$I15 -> 0.625 | ... M31: ='Hardware demands'!M28*'Variable costs'!$I15 -> 0.75
A32: =A23 -> Switches | B32: ='Hardware demands'!B29*'Variable costs'!$I16 -> 0.00092592593 | C32: ='Hardware demands'!C29*'Variable costs'!$I16 -> 0.00092592593 | D32: ='Hardware demands'!D29*'Variable costs'!$I16 -> 0.00092592593 | E32: ='Hardware demands'!E29*'Variable costs'!$I16 -> 0.00092592593 | F32: ='Hardware demands'!F29*'Variable costs'!$I16 -> 0.00092592593 | G32: ='Hardware demands'!G29*'Variable costs'!$I16 -> 0.00092592593 | H32: ='Hardware demands'!H29*'Variable costs'!$I16 -> 0.00092592593 | I32: ='Hardware demands'!I29*'Variable costs'!$I16 -> 0.00092592593 | ... M32: ='Hardware demands'!M29*'Variable costs'!$I16 -> 0.00092592593
A33: Constant costs | B33: ='Constant costs'!$B$26 -> 55.555556 | C33: ='Constant costs'!$B$26 -> 55.555556 | D33: ='Constant costs'!$B$26 -> 55.555556 | E33: ='Constant costs'!$B$26 -> 55.555556 | F33: ='Constant costs'!$B$26 -> 55.555556 | G33: ='Constant costs'!$B$26 -> 55.555556 | H33: ='Constant costs'!$B$26 -> 55.555556 | I33: ='Constant costs'!$B$26 -> 55.555556 | ... M33: ='Constant costs'!$B$26 -> 55.555556
A34: Total costs | B34: =SUM(B28:B33) -> 119.85509 | C34: =SUM(C28:C33) -> 125.97315 | D34: =SUM(D28:D33) -> 132.04954 | E34: =SUM(E28:E33) -> 139.62593 | F34: =SUM(F28:F33) -> 145.74398 | G34: =SUM(G28:G33) -> 151.86204 | H34: =SUM(H28:H33) -> 157.98009 | I34: =SUM(I28:I33) -> 164.09815 | ... M34: =SUM(M28:M33) -> 189.98704

Sheet Constant costs
A1: Constant costs
A8: Hardware
A9: Quantity | B9: Product name | C9: Product description | D9: Estimated costs | E9: Per month
